Workbook

Sheet Raw_Data
A1: Order_ID | B1: Order_Date | C1: Region | D1: City | E1: Salesperson | F1: Category | G1: Product | H1: Customer_Type | I1: Units_Sold | J1: Unit_Price | K1: Discount
A2: ORD-1108 | B2: 45665 | C2: West | D2: Pune | E2: Suresh Yadav | F2: Furniture | G2: Study Table | H2: Retail | I2: 18 | J2: 6500 | K2: 0
A3: ORD-1075 | B3: 45671 | C3: North | D3: Jaipur | E3: Vikas Jain | F3: Stationery | G3: Notebook Pack | H3: Online | I3: 19 | J3: 240 | K3: 0.05
A4: ORD-1010 | B4: 45674 | C4: West | D4: Pune | E4: Pooja Meena | F4: Stationery | G4: Notebook Pack | H4: Wholesale | I4: 8 | J4: 240 | K4: 0
A5: ORD-1101 | B5: 45678 | C5: West | D5: Pune | E5: Rohit Singh | F5: Electronics | G5: Smartphone X1 | H5: Wholesale | I5: 19 | J5: 11999 | K5: 0.1
A6: ORD-1005 | B6: 45680 | C6: North | D6: Bharatpur | E6: Kavita Joshi | F6: Stationery | G6: Printer Paper A4 | H6: Online | I6: 9 | J6: 320 | K6: 0
A7: ORD-1089 | B7: 45685 | C7: north | D7: Bengaluru | E7: Vikas Jain | F7: Furniture | G7: Study Table | H7: Online | I7: 2 | J7: 6500 | K7: 0
A8: ORD-1065 | B8: 45690 | C8: East | D8: Lucknow | E8: Suresh Yadav | F8: Furniture | G8: Bookshelf | H8: Wholesale | I8: 7 | J8: 3800 | K8: 0
A9: ORD-1098 | B9: 45694 | C9: West | D9: Pune | E9: Amit Sharma | F9: Furniture | G9: Study Table | H9: Retail | I9: 5 | J9: 6500 | K9: 0
A10: ORD-1036 | B10: 45695 | C10: East | D10: Kolkata | E10: Amit Sharma | F10: Stationery | G10: Pen Box | H10: Wholesale | I10: 11 | J10: 120 | K10: 0.1
A11: ORD-1033 | B11: 45699 | C11: East | D11: Lucknow | E11: Rohit Singh | F11: Furniture | G11: Office Chair | H11: Retail | I11: 17 | J11: 4200 | K11: 0.1
A12: ORD-1064 | B12: 45699 | C12: West | D12: Ahmedabad | E12: Rohit Singh | F12: Stationery | G12: Pen Box | H12: Retail | I12: 18 | J12: 120 | K12: 0
A13: ORD-1092 | B13: 45701 | C13: North | D13: Jaipur | E13: Neha Gupta | F13: Furniture | G13: Bookshelf | H13: Retail | I13: 10 | J13: 3800 | K13: 0.1
... A110: ORD-1111 | B110: 45917 | C110: West | D110: Mumbai | E110: Vikas Jain | F110: Stationery | G110: Pen Box | H110: Retail | I110: 11 | J110: 120 | K110: 0
A111: ORD-1024 | B111: 45921 | C111: West | D111: Mumbai | E111: Neha Gupta | F111: Electronics | G111: Smartphone X1 | H111: Wholesale | J111: 11999 | K111: 0.05
A112: ORD-1060 | B112: 45923 | C112: North | D112: Agra | E112: Kavita Joshi | F112: Furniture | G112: Office Chair | H112: Retail | I112: 23 | J112: 4200 | K112: 0.1
A113: ORD-1018 | B113: 45929 | C113: West | D113: Mumbai | E113: Amit Sharma | F113: Stationery | G113: Notebook Pack | H113: Online | I113: 18 | J113: 240 | K113: 0
A114: ORD-1020 | B114: 45930 | C114: North | D114: Delhi | E114: Rohit Singh | F114: Appliances | G114: Mixer Grinder | H114: Retail | I114: 25 | J114: 2600 | K114: 0.05
A115: ORD-1087 | B115: 45932 | C115: West | D115: Mumbai | E115: Rohit Singh | F115: Furniture | G115: Study Table | H115: Retail | I115: 4 | J115: 6500 | K115: 0
A116: ORD-1112 | B116: 45933 | C116: South | D116: Hyderabad | E116: Kavita Joshi | F116: Appliances | G116: Mixer Grinder | H116: Wholesale | I116: 15 | J116: 2600 | K116: 0
A117: ORD-1029 | B117: 45934 | C117: North | D117: Agra | E117: Amit Sharma | F117: Electronics | G117: LED TV 32" | H117: Retail | I117: 21 | J117: 14500 | K117: 0
A118: ORD-1012 | B118: 45945 | C118: West | D118: Ahmedabad | E118: Vikas Jain | F118: Furniture | G118: Office Chair | H118: Online | I118: 24 | J118: 4200 | K118: 0.1
A119: ORD-1125 | B119: 45947 | C119: South | D119: Bengaluru | E119: Amit Sharma | F119: Appliances | G119: Ceiling Fan | H119: Online | I119: 1 | J119: 1750 | K119: 0.05
A120: ORD-1139 | B120: 45947 | C120: North | D120: Delhi | E120: Neha Gupta | F120: Stationery | G120: Notebook Pack | H120: Retail | I120: 5 | J120: 240 | K120: 0.1
A121: ORD-1025 | B121: 45953 | C121: West | D121: Pune | E121: Kavita Joshi | F121: Furniture | G121: Bookshelf | H121: Retail | I121: 19 | J121: 3800 | K121: 0.05
A122: ORD-1127 | B122: 45954 | C122: North | D122: Delhi | E122: Pooja Meena | F122: Stationery | G122: Pen Box | H122: Online | I122: 2 | J122: 120 | K122: 0
A123: ORD-1003 | B123: 45959 | C123: North | D123: Jaipur | E123: Vikas Jain | F123: Appliances | G123: Mixer Grinder | H123: Retail | I123: 15 | J123: 2600 | K123: 0
... A125: ORD-1050 | B125: 45963 | C125: West | D125: Pune | E125: Suresh Yadav | F125: Stationery | G125: Notebook Pack | H125: Wholesale | I125: 4 | J125: 240 | K125: 0
A126: ORD-1058 | B126: 45970 | C126: West | D126: Mumbai | F126: Electronics | G126: Bluetooth Speaker | H126: Wholesale | I126: 16 | J126: 1800 | K126: 0.05
A127: ORD-1081 | B127: 45970 | C127: South | D127: Chennai | E127: Suresh Yadav | F127: Furniture | G127: Study Table | H127: Wholesale | I127: 19 | J127: 6500 | K127: 0
A128: ORD-1069 | B128: 45976 | C128: East | D128: Lucknow | E128: Amit Sharma | F128: Furniture | G128: Study Table | H128: Wholesale | I128: 5 | J128: 6500 | K128: 0.1
A129: ORD-1017 | B129: 45978 | C129: South | D129: Hyderabad | E129: Vikas Jain | F129: Furniture | G129: Bookshelf | H129: Online | I129: 4 | J129: 3800 | K129: 0.1
A130: ORD-1146 | B130: 45982 | C130: West | D130: Mumbai | E130: Pooja Meena | F130: Furniture | G130: Study Table | H130: Wholesale | I130: 20 | J130: 6500 | K130: 0.1
A131: ORD-1102 | B131: 45983 | C131: East | D131: Patna | E131: Kavita Joshi | F131: Furniture | G131: Bookshelf | H131: Retail | I131: 14 | J131: 3800 | K131: 0.05
A132: ORD-1133 | B132: 45983 | C132: South | D132: Hyderabad | E132: Kavita Joshi | F132: Furniture | G132: Bookshelf | H132: Online | I132: 3 | J132: 3800 | K132: 0
A133: ORD-1144 | B133: 45987 | C133: West | D133: Pune | E133: Amit Sharma | F133: Electronics | G133: Smartphone X1 | H133: Retail | I133: 15 | J133: 11999 | K133: 0.05
A134: ORD-1079 | B134: 45991 | C134: West | D134: Ahmedabad | E134: Vikas Jain | F134: Furniture | G134: Bookshelf | H134: Online | I134: 17 | J134: 3800 | K134: 0.1
A135: ORD-1105 | B135: 45994 | C135: South | D135: Bengaluru | E135: Kavita Joshi | F135: Appliances | G135: Water Purifier | H135: Wholesale | I135: 1 | J135: 8900 | K135: 0
A136: ORD-1077 | B136: 45996 | C136: North | D136: Delhi | E136: Pooja Meena | F136: Stationery | G136: Printer Paper A4 | H136: Retail | I136: 14 | J136: 320 | K136: 0.1
A137: ORD-1097 | B137: 45996 | C137: North | D137: Jaipur | E137: Neha Gupta | F137: Stationery | G137: Printer Paper A4 | H137: Wholesale | I137: 19 | J137: 320 | K137: 0
...

Sheet Cleaning_Log
A1: Data Cleaning Log — Sales Performance Analysis
A3: Step | B3: Action Taken
A4: 1 | B4: Raw rows loaded: 152
A5: 2 | B5: Removed 2 duplicate row(s) for Order_ID(s): ['ORD-1041', 'ORD-1076']
A6: 3 | B6: Standardized 'Region' column: trimmed whitespace, fixed casing (e.g. ' West ' -> 'West', 'north' -> 'North')
A7: 4 | B7: Filled 1 missing 'Salesperson' value(s) with 'Unknown'
A8: 5 | B8: Imputed 1 missing 'Units_Sold' value(s) using the median Units_Sold of the same Product Category
A9: 6 | B9: Added derived column 'Revenue' = Units_Sold x Unit_Price x (1 - Discount)
A10: 7 | B10: Added derived columns 'Order_Month' and 'Order_Month_Num' from Order_Date

Sheet Cleaned_Data
A1: Order_ID | B1: Order_Date | C1: Region | D1: City | E1: Salesperson | F1: Category | G1: Product | H1: Customer_Type | I1: Units_Sold | J1: Unit_Price | K1: Discount | L1: Revenue | M1: Order_Month | N1: Order_Month_Num
A2: ORD-1108 | B2: 45665 | C2: West | D2: Pune | E2: Suresh Yadav | F2: Furniture | G2: Study Table | H2: Retail | I2: 18 | J2: 6500 | K2: 0 | L2: =I2*J2*(1-K2) -> 117000 | M2: =TEXT(B2,"mmm") -> Jan | N2: =MONTH(B2) -> 1
A3: ORD-1075 | B3: 45671 | C3: North | D3: Jaipur | E3: Vikas Jain | F3: Stationery | G3: Notebook Pack | H3: Online | I3: 19 | J3: 240 | K3: 0.05 | L3: =I3*J3*(1-K3) -> 4332 | M3: =TEXT(B3,"mmm") -> Jan | N3: =MONTH(B3) -> 1
A4: ORD-1010 | B4: 45674 | C4: West | D4: Pune | E4: Pooja Meena | F4: Stationery | G4: Notebook Pack | H4: Wholesale | I4: 8 | J4: 240 | K4: 0 | L4: =I4*J4*(1-K4) -> 1920 | M4: =TEXT(B4,"mmm") -> Jan | N4: =MONTH(B4) -> 1
A5: ORD-1101 | B5: 45678 | C5: West | D5: Pune | E5: Rohit Singh | F5: Electronics | G5: Smartphone X1 | H5: Wholesale | I5: 19 | J5: 11999 | K5: 0.1 | L5: =I5*J5*(1-K5) -> 205182.9 | M5: =TEXT(B5,"mmm") -> Jan | N5: =MONTH(B5) -> 1
A6: ORD-1005 | B6: 45680 | C6: North | D6: Bharatpur | E6: Kavita Joshi | F6: Stationery | G6: Printer Paper A4 | H6: Online | I6: 9 | J6: 320 | K6: 0 | L6: =I6*J6*(1-K6) -> 2880 | M6: =TEXT(B6,"mmm") -> Jan | N6: =MONTH(B6) -> 1
A7: ORD-1089 | B7: 45685 | C7: North | D7: Bengaluru | E7: Vikas Jain | F7: Furniture | G7: Study Table | H7: Online | I7: 2 | J7: 6500 | K7: 0 | L7: =I7*J7*(1-K7) -> 13000 | M7: =TEXT(B7,"mmm") -> Jan | N7: =MONTH(B7) -> 1
A8: ORD-1065 | B8: 45690 | C8: East | D8: Lucknow | E8: Suresh Yadav | F8: Furniture | G8: Bookshelf | H8: Wholesale | I8: 7 | J8: 3800 | K8: 0 | L8: =I8*J8*(1-K8) -> 26600 | M8: =TEXT(B8,"mmm") -> Feb | N8: =MONTH(B8) -> 2
A9: ORD-1098 | B9: 45694 | C9: West | D9: Pune | E9: Amit Sharma | F9: Furniture | G9: Study Table | H9: Retail | I9: 5 | J9: 6500 | K9: 0 | L9: =I9*J9*(1-K9) -> 32500 | M9: =TEXT(B9,"mmm") -> Feb | N9: =MONTH(B9) -> 2
A10: ORD-1036 | B10: 45695 | C10: East | D10: Kolkata | E10: Amit Sharma | F10: Stationery | G10: Pen Box | H10: Wholesale | I10: 11 | J10: 120 | K10: 0.1 | L10: =I10*J10*(1-K10) -> 1188 | M10: =TEXT(B10,"mmm") -> Feb | N10: =MONTH(B10) -> 2
A11: ORD-1033 | B11: 45699 | C11: East | D11: Lucknow | E11: Rohit Singh | F11: Furniture | G11: Office Chair | H11: Retail | I11: 17 | J11: 4200 | K11: 0.1 | L11: =I11*J11*(1-K11) -> 64260 | M11: =TEXT(B11,"mmm") -> Feb | N11: =MONTH(B11) -> 2
A12: ORD-1064 | B12: 45699 | C12: West | D12: Ahmedabad | E12: Rohit Singh | F12: Stationery | G12: Pen Box | H12: Retail | I12: 18 | J12: 120 | K12: 0 | L12: =I12*J12*(1-K12) -> 2160 | M12: =TEXT(B12,"mmm") -> Feb | N12: =MONTH(B12) -> 2
A13: ORD-1092 | B13: 45701 | C13: North | D13: Jaipur | E13: Neha Gupta | F13: Furniture | G13: Bookshelf | H13: Retail | I13: 10 | J13: 3800 | K13: 0.1 | L13: =I13*J13*(1-K13) -> 34200 | M13: =TEXT(B13,"mmm") -> Feb | N13: =MONTH(B13) -> 2
... A151: ORD-1096 | B151: 46019 | C151: East | D151: Patna | E151: Vikas Jain | F151: Electronics | G151: Bluetooth Speaker | H151: Online | I151: 10 | J151: 1800 | K151: 0.05 | L151: =I151*J151*(1-K151) -> 17100 | M151: =TEXT(B151,"mmm") -> Dec | N151: =MONTH(B151) -> 12

Sheet Summary
A1: SALES PERFORMANCE — SUMMARY KPIs
A2: Total Revenue (₹) | B2: Total Orders | C2: Total Units Sold | D2: Avg Order Value (₹) | E2: Avg Discount
A3: =SUM(Cleaned_Data!L2:L151) -> 11922513 | B3: =COUNTA(Cleaned_Data!A2:A151) -> 150 | C3: =SUM(Cleaned_Data!I2:I151) -> 2029 | D3: =AVERAGE(Cleaned_Data!L2:L151) -> 79483.423 | E3: =AVERAGE(Cleaned_Data!K2:K151) -> 0.032333333
A6: REVENUE BY REGION
A7: Region | B7: Revenue (₹) | C7: Orders | D7: Units Sold
A8: East | B8: =SUMIF(Cleaned_Data!C2:C151,"East",Cleaned_Data!L2:L151) -> 5321204 | C8: =COUNTIF(Cleaned_Data!C2:C151,"East") -> 38 | D8: =SUMIF(Cleaned_Data!C2:C151,"East",Cleaned_Data!I2:I151) -> 494
A9: North | B9: =SUMIF(Cleaned_Data!C2:C151,"North",Cleaned_Data!L2:L151) -> 2191983 | C9: =COUNTIF(Cleaned_Data!C2:C151,"North") -> 43 | D9: =SUMIF(Cleaned_Data!C2:C151,"North",Cleaned_Data!I2:I151) -> 586
A10: South | B10: =SUMIF(Cleaned_Data!C2:C151,"South",Cleaned_Data!L2:L151) -> 2436349.5 | C10: =COUNTIF(Cleaned_Data!C2:C151,"South") -> 31 | D10: =SUMIF(Cleaned_Data!C2:C151,"South",Cleaned_Data!I2:I151) -> 412
A11: West | B11: =SUMIF(Cleaned_Data!C2:C151,"West",Cleaned_Data!L2:L151) -> 1972976.9 | C11: =COUNTIF(Cleaned_Data!C2:C151,"West") -> 38 | D11: =SUMIF(Cleaned_Data!C2:C151,"West",Cleaned_Data!I2:I151) -> 537
A14: REVENUE BY CATEGORY
A15: Category | B15: Revenue (₹) | C15: Orders | D15: Units Sold
A16: Appliances | B16: =SUMIF(Cleaned_Data!F2:F151,"Appliances",Cleaned_Data!L2:L151) -> 2017255 | C16: =COUNTIF(Cleaned_Data!F2:F151,"Appliances") -> 35 | D16: =SUMIF(Cleaned_Data!F2:F151,"Appliances",Cleaned_Data!I2:I151) -> 485
A17: Electronics | B17: =SUMIF(Cleaned_Data!F2:F151,"Electronics",Cleaned_Data!L2:L151) -> 7651326.5 | C17: =COUNTIF(Cleaned_Data!F2:F151,"Electronics") -> 31 | D17: =SUMIF(Cleaned_Data!F2:F151,"Electronics",Cleaned_Data!I2:I151) -> 476
A18: Furniture | B18: =SUMIF(Cleaned_Data!F2:F151,"Furniture",Cleaned_Data!L2:L151) -> 2119190 | C18: =COUNTIF(Cleaned_Data!F2:F151,"Furniture") -> 36 | D18: =SUMIF(Cleaned_Data!F2:F151,"Furniture",Cleaned_Data!I2:I151) -> 451
A19: Stationery | B19: =SUMIF(Cleaned_Data!F2:F151,"Stationery",Cleaned_Data!L2:L151) -> 134742 | C19: =COUNTIF(Cleaned_Data!F2:F151,"Stationery") -> 48 | D19: =SUMIF(Cleaned_Data!F2:F151,"Stationery",Cleaned_Data!I2:I151) -> 617
A22: REVENUE BY CUSTOMER TYPE
A23: Customer Type | B23: Revenue (₹) | C23: Orders | D23: Units Sold
A24: Online | B24: =SUMIF(Cleaned_Data!H2:H151,"Online",Cleaned_Data!L2:L151) -> 1517619.5 | C24: =COUNTIF(Cleaned_Data!H2:H151,"Online") -> 47 | D24: =SUMIF(Cleaned_Data!H2:H151,"Online",Cleaned_Data!I2:I151) -> 590
A25: Retail | B25: =SUMIF(Cleaned_Data!H2:H151,"Retail",Cleaned_Data!L2:L151) -> 6347073.2 | C25: =COUNTIF(Cleaned_Data!H2:H151,"Retail") -> 55 | D25: =SUMIF(Cleaned_Data!H2:H151,"Retail",Cleaned_Data!I2:I151) -> 805
A26: Wholesale | B26: =SUMIF(Cleaned_Data!H2:H151,"Wholesale",Cleaned_Data!L2:L151) -> 4057820.7 | C26: =COUNTIF(Cleaned_Data!H2:H151,"Wholesale") -> 48 | D26: =SUMIF(Cleaned_Data!H2:H151,"Wholesale",Cleaned_Data!I2:I151) -> 634
A29: REVENUE BY SALESPERSON
A30: Salesperson | B30: Revenue (₹) | C30: Orders | D30: Units Sold
A31: Amit Sharma | B31: =SUMIF(Cleaned_Data!E2:E151,"Amit Sharma",Cleaned_Data!L2:L151) -> 1469612.8 | C31: =COUNTIF(Cleaned_Data!E2:E151,"Amit Sharma") -> 22 | D31: =SUMIF(Cleaned_Data!E2:E151,"Amit Sharma",Cleaned_Data!I2:I151) -> 263
A32: Kavita Joshi | B32: =SUMIF(Cleaned_Data!E2:E151,"Kavita Joshi",Cleaned_Data!L2:L151) -> 1582548 | C32: =COUNTIF(Cleaned_Data!E2:E151,"Kavita Joshi") -> 24 | D32: =SUMIF(Cleaned_Data!E2:E151,"Kavita Joshi",Cleaned_Data!I2:I151) -> 321
A33: Neha Gupta | B33: =SUMIF(Cleaned_Data!E2:E151,"Neha Gupta",Cleaned_Data!L2:L151) -> 1324786.8 | C33: =COUNTIF(Cleaned_Data!E2:E151,"Neha Gupta") -> 19 | D33: =SUMIF(Cleaned_Data!E2:E151,"Neha Gupta",Cleaned_Data!I2:I151) -> 277
A34: Pooja Meena | B34: =SUMIF(Cleaned_Data!E2:E151,"Pooja Meena",Cleaned_Data!L2:L151) -> 881412 | C34: =COUNTIF(Cleaned_Data!E2:E151,"Pooja Meena") -> 16 | D34: =SUMIF(Cleaned_Data!E2:E151,"Pooja Meena",Cleaned_Data!I2:I151) -> 169
A35: Priya Verma | B35: =SUMIF(Cleaned_Data!E2:E151,"Priya Verma",Cleaned_Data!L2:L151) -> 1281889 | C35: =COUNTIF(Cleaned_Data!E2:E151,"Priya Verma") -> 12 | D35: =SUMIF(Cleaned_Data!E2:E151,"Priya Verma",Cleaned_Data!I2:I151) -> 135
A36: Rohit Singh | B36: =SUMIF(Cleaned_Data!E2:E151,"Rohit Singh",Cleaned_Data!L2:L151) -> 1224080.9 | C36: =COUNTIF(Cleaned_Data!E2:E151,"Rohit Singh") -> 15 | D36: =SUMIF(Cleaned_Data!E2:E151,"Rohit Singh",Cleaned_Data!I2:I151) -> 216
A37: Suresh Yadav | B37: =SUMIF(Cleaned_Data!E2:E151,"Suresh Yadav",Cleaned_Data!L2:L151) -> 1433717 | C37: =COUNTIF(Cleaned_Data!E2:E151,"Suresh Yadav") -> 16 | D37: =SUMIF(Cleaned_Data!E2:E151,"Suresh Yadav",Cleaned_Data!I2:I151) -> 263
A38: Unknown | B38: =SUMIF(Cleaned_Data!E2:E151,"Unknown",Cleaned_Data!L2:L151) -> 27360 | C38: =COUNTIF(Cleaned_Data!E2:E151,"Unknown") -> 1 | D38: =SUMIF(Cleaned_Data!E2:E151,"Unknown",Cleaned_Data!I2:I151) -> 16
A39: Vikas Jain | B39: =SUMIF(Cleaned_Data!E2:E151,"Vikas Jain",Cleaned_Data!L2:L151) -> 2697107 | C39: =COUNTIF(Cleaned_Data!E2:E151,"Vikas Jain") -> 25 | D39: =SUMIF(Cleaned_Data!E2:E151,"Vikas Jain",Cleaned_Data!I2:I151) -> 369
A42: REVENUE BY PRODUCT
A43: Product | B43: Revenue (₹) | C43: Orders | D43: Units Sold
A44: Laptop Pro 14 | B44: =SUMIF(Cleaned_Data!G2:G151,"Laptop Pro 14",Cleaned_Data!L2:L151) -> 4218125 | C44: =COUNTIF(Cleaned_Data!G2:G151,"Laptop Pro 14") -> 6 | D44: =SUMIF(Cleaned_Data!G2:G151,"Laptop Pro 14",Cleaned_Data!I2:I151) -> 103
A45: LED TV 32" | B45: =SUMIF(Cleaned_Data!G2:G151,"LED TV 32""",Cleaned_Data!L2:L151) -> 2032900 | C45: =COUNTIF(Cleaned_Data!G2:G151,"LED TV 32""") -> 9 | D45: =SUMIF(Cleaned_Data!G2:G151,"LED TV 32""",Cleaned_Data!I2:I151) -> 144
A46: Water Purifier | B46: =SUMIF(Cleaned_Data!G2:G151,"Water Purifier",Cleaned_Data!L2:L151) -> 1241550 | C46: =COUNTIF(Cleaned_Data!G2:G151,"Water Purifier") -> 12 | D46: =SUMIF(Cleaned_Data!G2:G151,"Water Purifier",Cleaned_Data!I2:I151) -> 143
A47: Smartphone X1 | B47: =SUMIF(Cleaned_Data!G2:G151,"Smartphone X1",Cleaned_Data!L2:L151) -> 1182501.4 | C47: =COUNTIF(Cleaned_Data!G2:G151,"Smartphone X1") -> 7 | D47: =SUMIF(Cleaned_Data!G2:G151,"Smartphone X1",Cleaned_Data!I2:I151) -> 104
A48: Study Table | B48: =SUMIF(Cleaned_Data!G2:G151,"Study Table",Cleaned_Data!L2:L151) -> 1018550 | C48: =COUNTIF(Cleaned_Data!G2:G151,"Study Table") -> 13 | D48: =SUMIF(Cleaned_Data!G2:G151,"Study Table",Cleaned_Data!I2:I151) -> 161
A49: Office Chair | B49: =SUMIF(Cleaned_Data!G2:G151,"Office Chair",Cleaned_Data!L2:L151) -> 648060 | C49: =COUNTIF(Cleaned_Data!G2:G151,"Office Chair") -> 10 | D49: =SUMIF(Cleaned_Data!G2:G151,"Office Chair",Cleaned_Data!I2:I151) -> 164
A50: Mixer Grinder | B50: =SUMIF(Cleaned_Data!G2:G151,"Mixer Grinder",Cleaned_Data!L2:L151) -> 585130 | C50: =COUNTIF(Cleaned_Data!G2:G151,"Mixer Grinder") -> 14 | D50: =SUMIF(Cleaned_Data!G2:G151,"Mixer Grinder",Cleaned_Data!I2:I151) -> 230
...

Sheet Dashboard
A1: SALES PERFORMANCE DASHBOARD — 2025
A3: Total Revenue (₹) | C3: Total Orders | E3: Total Units Sold | G3: Avg Order Value (₹) | I3: Avg Discount
A4: =Summary!A3 -> 11922513 | C4: =Summary!B3 -> 150 | E4: =Summary!C3 -> 2029 | G4: =Summary!D3 -> 79483.423 | I4: =Summary!E3 -> 0.032333333
